2021-12-25 14:21:23,135 ERROR: Exception on /unfollow/dodo [POST] [in /Users/vaibhavx/Documents/Python_Projects/microblog/venv/lib/python3.8/site-packages/flask/app.py:1891]
Traceback (most recent call last):
  File "/Users/vaibhavx/Documents/Python_Projects/microblog/venv/lib/python3.8/site-packages/flask/app.py", line 2447, in wsgi_app
    response = self.full_dispatch_request()
  File "/Users/vaibhavx/Documents/Python_Projects/microblog/venv/lib/python3.8/site-packages/flask/app.py", line 1952, in full_dispatch_request
    rv = self.handle_user_exception(e)
  File "/Users/vaibhavx/Documents/Python_Projects/microblog/venv/lib/python3.8/site-packages/flask/app.py", line 1821, in handle_user_exception
    reraise(exc_type, exc_value, tb)
  File "/Users/vaibhavx/Documents/Python_Projects/microblog/venv/lib/python3.8/site-packages/flask/_compat.py", line 39, in reraise
    raise value
  File "/Users/vaibhavx/Documents/Python_Projects/microblog/venv/lib/python3.8/site-packages/flask/app.py", line 1950, in full_dispatch_request
    rv = self.dispatch_request()
  File "/Users/vaibhavx/Documents/Python_Projects/microblog/venv/lib/python3.8/site-packages/flask/app.py", line 1936, in dispatch_request
    return self.view_functions[rule.endpoint](**req.view_args)
  File "/Users/vaibhavx/Documents/Python_Projects/microblog/venv/lib/python3.8/site-packages/flask_login/utils.py", line 272, in decorated_view
    return func(*args, **kwargs)
  File "/Users/vaibhavx/Documents/Python_Projects/microblog/app/routes.py", line 122, in unfollow
    if user == current_user:
UnboundLocalError: local variable 'current_user' referenced before assignment
2021-12-25 14:21:36,816 INFO: Microblog startup [in /Users/vaibhavx/Documents/Python_Projects/microblog/app/__init__.py:44]
