2021-12-25 14:15:33,679 ERROR: Exception on /user/dodo [GET] [in /Users/vaibhavx/Documents/Python_Projects/microblog/venv/lib/python3.8/site-packages/flask/app.py:1891]
Traceback (most recent call last):
  File "/Users/vaibhavx/Documents/Python_Projects/microblog/venv/lib/python3.8/site-packages/flask/app.py", line 2447, in wsgi_app
    response = self.full_dispatch_request()
  File "/Users/vaibhavx/Documents/Python_Projects/microblog/venv/lib/python3.8/site-packages/flask/app.py", line 1952, in full_dispatch_request
    rv = self.handle_user_exception(e)
  File "/Users/vaibhavx/Documents/Python_Projects/microblog/venv/lib/python3.8/site-packages/flask/app.py", line 1821, in handle_user_exception
    reraise(exc_type, exc_value, tb)
  File "/Users/vaibhavx/Documents/Python_Projects/microblog/venv/lib/python3.8/site-packages/flask/_compat.py", line 39, in reraise
    raise value
  File "/Users/vaibhavx/Documents/Python_Projects/microblog/venv/lib/python3.8/site-packages/flask/app.py", line 1950, in full_dispatch_request
    rv = self.dispatch_request()
  File "/Users/vaibhavx/Documents/Python_Projects/microblog/venv/lib/python3.8/site-packages/flask/app.py", line 1936, in dispatch_request
    return self.view_functions[rule.endpoint](**req.view_args)
  File "/Users/vaibhavx/Documents/Python_Projects/microblog/venv/lib/python3.8/site-packages/flask_login/utils.py", line 272, in decorated_view
    return func(*args, **kwargs)
  File "/Users/vaibhavx/Documents/Python_Projects/microblog/app/routes.py", line 71, in user
    return render_template('user.html', user=user, posts=posts, form=form)
  File "/Users/vaibhavx/Documents/Python_Projects/microblog/venv/lib/python3.8/site-packages/flask/templating.py", line 137, in render_template
    return _render(
  File "/Users/vaibhavx/Documents/Python_Projects/microblog/venv/lib/python3.8/site-packages/flask/templating.py", line 120, in _render
    rv = template.render(context)
  File "/Users/vaibhavx/Documents/Python_Projects/microblog/venv/lib/python3.8/site-packages/jinja2/environment.py", line 1090, in render
    self.environment.handle_exception()
  File "/Users/vaibhavx/Documents/Python_Projects/microblog/venv/lib/python3.8/site-packages/jinja2/environment.py", line 832, in handle_exception
    reraise(*rewrite_traceback_stack(source=source))
  File "/Users/vaibhavx/Documents/Python_Projects/microblog/venv/lib/python3.8/site-packages/jinja2/_compat.py", line 28, in reraise
    raise value.with_traceback(tb)
  File "/Users/vaibhavx/Documents/Python_Projects/microblog/app/templates/user.html", line 1, in top-level template code
    {% extends "base.html" %}
  File "/Users/vaibhavx/Documents/Python_Projects/microblog/app/templates/base.html", line 30, in top-level template code
    {% block content %}{% endblock %}
  File "/Users/vaibhavx/Documents/Python_Projects/microblog/app/templates/user.html", line 25, in block "content"
    {{ form.submit(value+'Unfollow') }}
jinja2.exceptions.UndefinedError: 'value' is undefined
2021-12-25 14:16:03,652 ERROR: Exception on /user/dodo [GET] [in /Users/vaibhavx/Documents/Python_Projects/microblog/venv/lib/python3.8/site-packages/flask/app.py:1891]
Traceback (most recent call last):
  File "/Users/vaibhavx/Documents/Python_Projects/microblog/venv/lib/python3.8/site-packages/flask/app.py", line 2447, in wsgi_app
    response = self.full_dispatch_request()
  File "/Users/vaibhavx/Documents/Python_Projects/microblog/venv/lib/python3.8/site-packages/flask/app.py", line 1952, in full_dispatch_request
    rv = self.handle_user_exception(e)
  File "/Users/vaibhavx/Documents/Python_Projects/microblog/venv/lib/python3.8/site-packages/flask/app.py", line 1821, in handle_user_exception
    reraise(exc_type, exc_value, tb)
  File "/Users/vaibhavx/Documents/Python_Projects/microblog/venv/lib/python3.8/site-packages/flask/_compat.py", line 39, in reraise
    raise value
  File "/Users/vaibhavx/Documents/Python_Projects/microblog/venv/lib/python3.8/site-packages/flask/app.py", line 1950, in full_dispatch_request
    rv = self.dispatch_request()
  File "/Users/vaibhavx/Documents/Python_Projects/microblog/venv/lib/python3.8/site-packages/flask/app.py", line 1936, in dispatch_request
    return self.view_functions[rule.endpoint](**req.view_args)
  File "/Users/vaibhavx/Documents/Python_Projects/microblog/venv/lib/python3.8/site-packages/flask_login/utils.py", line 272, in decorated_view
    return func(*args, **kwargs)
  File "/Users/vaibhavx/Documents/Python_Projects/microblog/app/routes.py", line 71, in user
    return render_template('user.html', user=user, posts=posts, form=form)
  File "/Users/vaibhavx/Documents/Python_Projects/microblog/venv/lib/python3.8/site-packages/flask/templating.py", line 137, in render_template
    return _render(
  File "/Users/vaibhavx/Documents/Python_Projects/microblog/venv/lib/python3.8/site-packages/flask/templating.py", line 120, in _render
    rv = template.render(context)
  File "/Users/vaibhavx/Documents/Python_Projects/microblog/venv/lib/python3.8/site-packages/jinja2/environment.py", line 1090, in render
    self.environment.handle_exception()
  File "/Users/vaibhavx/Documents/Python_Projects/microblog/venv/lib/python3.8/site-packages/jinja2/environment.py", line 832, in handle_exception
    reraise(*rewrite_traceback_stack(source=source))
  File "/Users/vaibhavx/Documents/Python_Projects/microblog/venv/lib/python3.8/site-packages/jinja2/_compat.py", line 28, in reraise
    raise value.with_traceback(tb)
  File "/Users/vaibhavx/Documents/Python_Projects/microblog/app/templates/user.html", line 1, in top-level template code
    {% extends "base.html" %}
  File "/Users/vaibhavx/Documents/Python_Projects/microblog/app/templates/base.html", line 30, in top-level template code
    {% block content %}{% endblock %}
  File "/Users/vaibhavx/Documents/Python_Projects/microblog/app/templates/user.html", line 25, in block "content"
    {{ form.submit(value='Unfollow') }}
jinja2.exceptions.UndefinedError: 'value' is undefined
2021-12-25 14:16:33,313 INFO: Microblog startup [in /Users/vaibhavx/Documents/Python_Projects/microblog/app/__init__.py:44]
2021-12-25 14:16:50,767 ERROR: Exception on /unfollow/dodo [POST] [in /Users/vaibhavx/Documents/Python_Projects/microblog/venv/lib/python3.8/site-packages/flask/app.py:1891]
Traceback (most recent call last):
  File "/Users/vaibhavx/Documents/Python_Projects/microblog/venv/lib/python3.8/site-packages/flask/app.py", line 2447, in wsgi_app
    response = self.full_dispatch_request()
  File "/Users/vaibhavx/Documents/Python_Projects/microblog/venv/lib/python3.8/site-packages/flask/app.py", line 1952, in full_dispatch_request
    rv = self.handle_user_exception(e)
  File "/Users/vaibhavx/Documents/Python_Projects/microblog/venv/lib/python3.8/site-packages/flask/app.py", line 1821, in handle_user_exception
    reraise(exc_type, exc_value, tb)
  File "/Users/vaibhavx/Documents/Python_Projects/microblog/venv/lib/python3.8/site-packages/flask/_compat.py", line 39, in reraise
    raise value
  File "/Users/vaibhavx/Documents/Python_Projects/microblog/venv/lib/python3.8/site-packages/flask/app.py", line 1950, in full_dispatch_request
    rv = self.dispatch_request()
  File "/Users/vaibhavx/Documents/Python_Projects/microblog/venv/lib/python3.8/site-packages/flask/app.py", line 1936, in dispatch_request
    return self.view_functions[rule.endpoint](**req.view_args)
  File "/Users/vaibhavx/Documents/Python_Projects/microblog/venv/lib/python3.8/site-packages/flask_login/utils.py", line 272, in decorated_view
    return func(*args, **kwargs)
  File "/Users/vaibhavx/Documents/Python_Projects/microblog/app/routes.py", line 122, in unfollow
    if user == current_user:
UnboundLocalError: local variable 'current_user' referenced before assignment
2021-12-25 14:17:59,770 ERROR: Exception on /unfollow/dodo [POST] [in /Users/vaibhavx/Documents/Python_Projects/microblog/venv/lib/python3.8/site-packages/flask/app.py:1891]
Traceback (most recent call last):
  File "/Users/vaibhavx/Documents/Python_Projects/microblog/venv/lib/python3.8/site-packages/flask/app.py", line 2447, in wsgi_app
    response = self.full_dispatch_request()
  File "/Users/vaibhavx/Documents/Python_Projects/microblog/venv/lib/python3.8/site-packages/flask/app.py", line 1952, in full_dispatch_request
    rv = self.handle_user_exception(e)
  File "/Users/vaibhavx/Documents/Python_Projects/microblog/venv/lib/python3.8/site-packages/flask/app.py", line 1821, in handle_user_exception
    reraise(exc_type, exc_value, tb)
  File "/Users/vaibhavx/Documents/Python_Projects/microblog/venv/lib/python3.8/site-packages/flask/_compat.py", line 39, in reraise
    raise value
  File "/Users/vaibhavx/Documents/Python_Projects/microblog/venv/lib/python3.8/site-packages/flask/app.py", line 1950, in full_dispatch_request
    rv = self.dispatch_request()
  File "/Users/vaibhavx/Documents/Python_Projects/microblog/venv/lib/python3.8/site-packages/flask/app.py", line 1936, in dispatch_request
    return self.view_functions[rule.endpoint](**req.view_args)
  File "/Users/vaibhavx/Documents/Python_Projects/microblog/venv/lib/python3.8/site-packages/flask_login/utils.py", line 272, in decorated_view
    return func(*args, **kwargs)
  File "/Users/vaibhavx/Documents/Python_Projects/microblog/app/routes.py", line 122, in unfollow
    if user == current_user:
UnboundLocalError: local variable 'current_user' referenced before assignment
